# launch_function works even on exception

    Code
      result$error
    Output
      <simpleError in my_fun(): argument "sec" is missing, with no default>

